<?xml version="1.0" ?>
<!-- =================================================================================== -->
<!-- |    This document was autogenerated by xacro from amir_mecanum3.xacro            | -->
<!-- |    EDITING THIS FILE BY HAND IS NOT RECOMMENDED                                 | -->
<!-- =================================================================================== -->
<robot name="amir_mecanum3">
  <material name="silver">
    <color rgba="0.800 0.800 0.800 1.000"/>
  </material>
  <material name="dark_silver">
    <color rgba="0.400 0.400 0.400 1.000"/>
  </material>
  <material name="dark_grey">
    <color rgba="0.200 0.200 0.200 1.000"/>
  </material>
  <material name="black">
    <color rgba="0.100 0.100 0.100 1.000"/>
  </material>
  <!-- LRF: TG30 -->
  <!-- DATA: http://www.ydlidar.com/Public/upload/files/2022-06-21/YDLIDAR%20TG30%20Data%20Sheet%20V1.4(211230).pdf -->
  <gazebo reference="front_lrf_link">
    <material>Gazebo/FlatBlack</material>
    <selfCollide>true</selfCollide>
    <sensor name="tg30_lidar_front" type="ray">
      <pose>0 0 0 0 0 0</pose>
      <visualize>false</visualize>
      <update_rate>12</update_rate>
      <ray>
        <scan>
          <horizontal>
            <samples>1636</samples>
            <resolution>0.22</resolution>
            <min_angle>0.0</min_angle>
            <max_angle>6.28319</max_angle>
          </horizontal>
        </scan>
        <range>
          <min>0.05</min>
          <max>30.0</max>
          <resolution>0.01</resolution>
        </range>
        <noise>
          <type>gaussian</type>
          <mean>0.0</mean>
          <stddev>0.01</stddev>
        </noise>
      </ray>
      <!-- <plugin filename="libgazebo_ros_laser.so" name="gazebo_ros_tg30_lidar_front_controller">
        <topicName>scan</topicName>
        <frameName>front_lrf_link</frameName>
      </plugin> -->
    </sensor>
  </gazebo>
  <gazebo reference="back_lrf_link">
    <material>Gazebo/FlatBlack</material>
    <selfCollide>true</selfCollide>
    <sensor name="tg30_lidar_back" type="ray">
      <pose>0 0 0 0 0 0</pose>
      <visualize>false</visualize>
      <update_rate>12</update_rate>
      <ray>
        <scan>
          <horizontal>
            <samples>1636</samples>
            <resolution>0.22</resolution>
            <min_angle>0.0</min_angle>
            <max_angle>6.28319</max_angle>
          </horizontal>
        </scan>
        <range>
          <min>0.05</min>
          <max>30.0</max>
          <resolution>0.01</resolution>
        </range>
        <noise>
          <type>gaussian</type>
          <mean>0.0</mean>
          <stddev>0.01</stddev>
        </noise>
      </ray>
      <!-- <plugin filename="libgazebo_ros_laser.so" name="gazebo_ros_tg30_lidar_back_controller">
        <topicName>scan</topicName>
        <frameName>back_lrf_link</frameName>
      </plugin> -->
    </sensor>
  </gazebo>
  <!-- front LRF sensor joints and links -->
  <joint name="front_lrf_joint" type="fixed">
    <parent link="base_link"/>
    <child link="front_lrf_link"/>
    <origin rpy="0 0 1.5707963267948966" xyz="0.0 0.2 0.1959"/>
  </joint>
  <link name="front_lrf_link">
    <inertial>
      <origin rpy="0 0 0" xyz="-0.004299 -0.000337 -0.018037"/>
      <mass value="0.200"/>
      <inertia ixx="0.0001205" ixy="0.00" ixz="0.00" iyy="0.0001561" iyz="0.00" izz="0.0001977"/>
    </inertial>
    <visual>
      <origin rpy="0 0 0" xyz="0 0 0"/>
      <geometry>
        <mesh filename="package://vs_rover_options_description/meshes/lrf/tg30.stl" scale="0.001 0.001 0.001"/>
      </geometry>
      <material name="black"/>
    </visual>
    <collision>
      <origin rpy="0 0 0" xyz="0 0 0"/>
      <geometry>
        <mesh filename="package://vs_rover_options_description/meshes/lrf/tg30.stl" scale="0.001 0.001 0.001"/>
      </geometry>
    </collision>
  </link>
  <!-- back LRF sensor joints and links -->
  <joint name="back_lrf_joint" type="fixed">
    <parent link="base_link"/>
    <child link="back_lrf_link"/>
    <origin rpy="0 0 -1.5707963267948966" xyz="0.0 -0.2 0.1959"/>
  </joint>
  <link name="back_lrf_link">
    <inertial>
      <origin rpy="0 0 0" xyz="-0.004299 -0.000337 -0.018037"/>
      <mass value="0.200"/>
      <inertia ixx="0.0001205" ixy="0.00" ixz="0.00" iyy="0.0001561" iyz="0.00" izz="0.0001977"/>
    </inertial>
    <visual>
      <origin rpy="0 0 0" xyz="0 0 0"/>
      <geometry>
        <mesh filename="package://vs_rover_options_description/meshes/lrf/tg30.stl" scale="0.001 0.001 0.001"/>
      </geometry>
      <material name="black"/>
    </visual>
    <collision>
      <origin rpy="0 0 0" xyz="0 0 0"/>
      <geometry>
        <mesh filename="package://vs_rover_options_description/meshes/lrf/tg30.stl" scale="0.001 0.001 0.001"/>
      </geometry>
    </collision>
  </link>
  <link name="base_footprint"/>
  <joint name="base_joint" type="fixed">
    <parent link="base_footprint"/>
    <child link="base_link"/>
    <origin rpy="0 0 -1.5707963267948966" xyz="0 0 0"/>
  </joint>
  <link name="base_link">
    <inertial>
      <origin rpy="0 0 0" xyz="8.039076182406018e-05 -0.001484050423595346 0.11040223412633365"/>
      <mass value="51.54953324093924"/>
      <inertia ixx="0.451406" ixy="0.000784" ixz="-0.000134" iyy="0.211369" iyz="0.000199" izz="0.557559"/>
    </inertial>
    <visual>
      <origin rpy="0 0 0" xyz="0 0 0"/>
      <geometry>
        <mesh filename="package://mecanumrover_description/meshes/base_link.stl" scale="0.001 0.001 0.001"/>
      </geometry>
      <material name="silver"/>
    </visual>
    <collision>
      <origin rpy="0 0 0" xyz="0 0 0"/>
      <geometry>
        <mesh filename="package://mecanumrover_description/meshes/base_link.stl" scale="0.001 0.001 0.001"/>
      </geometry>
    </collision>
  </link>
  <link name="front_left_wheel_1">
    <inertial>
      <origin rpy="0 0 0" xyz="-0.03247844667661433 -1.7208456881689926e-15 1.3877787807814457e-17"/>
      <mass value="6.210672529256712"/>
      <inertia ixx="0.017207" ixy="0.0" ixz="-0.0" iyy="0.009618" iyz="0.0" izz="0.009618"/>
    </inertial>
    <visual>
      <origin rpy="0 0 0" xyz="0.0875 -0.12 -0.076"/>
      <geometry>
        <mesh filename="package://mecanumrover_description/meshes/front_left_wheel_1.stl" scale="0.001 0.001 0.001"/>
      </geometry>
      <material name="dark_grey"/>
    </visual>
    <collision>
      <origin rpy="0 0 0" xyz="0.0875 -0.12 -0.076"/>
      <geometry>
        <mesh filename="package://mecanumrover_description/meshes/front_left_wheel_1.stl" scale="0.001 0.001 0.001"/>
      </geometry>
    </collision>
  </link>
  <link name="front_right_wheel_1">
    <inertial>
      <origin rpy="0 0 0" xyz="0.032478446676614314 -3.7470027081099033e-16 1.3877787807814457e-17"/>
      <mass value="6.210672529256714"/>
      <inertia ixx="0.017207" ixy="-0.0" ixz="0.0" iyy="0.009618" iyz="0.0" izz="0.009618"/>
    </inertial>
    <visual>
      <origin rpy="0 0 0" xyz="-0.0875 -0.12 -0.076"/>
      <geometry>
        <mesh filename="package://mecanumrover_description/meshes/front_right_wheel_1.stl" scale="0.001 0.001 0.001"/>
      </geometry>
      <material name="dark_grey"/>
    </visual>
    <collision>
      <origin rpy="0 0 0" xyz="-0.0875 -0.12 -0.076"/>
      <geometry>
        <mesh filename="package://mecanumrover_description/meshes/front_right_wheel_1.stl" scale="0.001 0.001 0.001"/>
      </geometry>
    </collision>
  </link>
  <link name="back_right_wheel_1">
    <inertial>
      <origin rpy="0 0 0" xyz="0.03247844667661433 1.7208456881689926e-15 1.3877787807814457e-17"/>
      <mass value="6.210672529256712"/>
      <inertia ixx="0.017207" ixy="0.0" ixz="0.0" iyy="0.009618" iyz="0.0" izz="0.009618"/>
    </inertial>
    <visual>
      <origin rpy="0 0 0" xyz="-0.0875 0.12 -0.076"/>
      <geometry>
        <mesh filename="package://mecanumrover_description/meshes/back_right_wheel_1.stl" scale="0.001 0.001 0.001"/>
      </geometry>
      <material name="dark_grey"/>
    </visual>
    <collision>
      <origin rpy="0 0 0" xyz="-0.0875 0.12 -0.076"/>
      <geometry>
        <mesh filename="package://mecanumrover_description/meshes/back_right_wheel_1.stl" scale="0.001 0.001 0.001"/>
      </geometry>
    </collision>
  </link>
  <link name="back_left_wheel_1">
    <inertial>
      <origin rpy="0 0 0" xyz="-0.03247844667661433 3.7470027081099033e-16 0.0"/>
      <mass value="6.210672529256715"/>
      <inertia ixx="0.017207" ixy="-0.0" ixz="0.0" iyy="0.009618" iyz="0.0" izz="0.009618"/>
    </inertial>
    <visual>
      <origin rpy="0 0 0" xyz="0.0875 0.12 -0.076"/>
      <geometry>
        <mesh filename="package://mecanumrover_description/meshes/back_left_wheel_1.stl" scale="0.001 0.001 0.001"/>
      </geometry>
      <material name="dark_grey"/>
    </visual>
    <collision>
      <origin rpy="0 0 0" xyz="0.0875 0.12 -0.076"/>
      <geometry>
        <mesh filename="package://mecanumrover_description/meshes/back_left_wheel_1.stl" scale="0.001 0.001 0.001"/>
      </geometry>
    </collision>
  </link>
  <joint name="front_left_joint" type="continuous">
    <origin rpy="0 0 0" xyz="-0.0875 0.12 0.076"/>
    <parent link="base_link"/>
    <child link="front_left_wheel_1"/>
    <axis xyz="-1.0 0.0 0.0"/>
  </joint>
  <joint name="front_right_joint" type="continuous">
    <origin rpy="0 0 0" xyz="0.0875 0.12 0.076"/>
    <parent link="base_link"/>
    <child link="front_right_wheel_1"/>
    <axis xyz="1.0 0.0 0.0"/>
  </joint>
  <joint name="back_right_joint" type="continuous">
    <origin rpy="0 0 0" xyz="0.0875 -0.12 0.076"/>
    <parent link="base_link"/>
    <child link="back_right_wheel_1"/>
    <axis xyz="1.0 0.0 0.0"/>
  </joint>
  <joint name="back_left_joint" type="continuous">
    <origin rpy="0 0 0" xyz="-0.0875 -0.12 0.076"/>
    <parent link="base_link"/>
    <child link="back_left_wheel_1"/>
    <axis xyz="-1.0 0.0 0.0"/>
  </joint>
  <material name="silver-amir">
    <color rgba="0.699 0.699 0.699 1.000"/>
  </material>
  <transmission name="Joint_1_tran">
    <type>transmission_interface/SimpleTransmission</type>
    <joint name="Joint_1">
      <hardwareInterface>hardware_interface/VelocityJointInterface</hardwareInterface>
    </joint>
    <actuator name="Joint_1_actr">
      <hardwareInterface>hardware_interface/VelocityJointInterface</hardwareInterface>
      <mechanicalReduction>1</mechanicalReduction>
    </actuator>
  </transmission>
  <transmission name="Joint_2_tran">
    <type>transmission_interface/SimpleTransmission</type>
    <joint name="Joint_2">
      <hardwareInterface>hardware_interface/VelocityJointInterface</hardwareInterface>
    </joint>
    <actuator name="Joint_2_actr">
      <hardwareInterface>hardware_interface/VelocityJointInterface</hardwareInterface>
      <mechanicalReduction>1</mechanicalReduction>
    </actuator>
  </transmission>
  <transmission name="Joint_3_tran">
    <type>transmission_interface/SimpleTransmission</type>
    <joint name="Joint_3">
      <hardwareInterface>hardware_interface/VelocityJointInterface</hardwareInterface>
    </joint>
    <actuator name="Joint_3_actr">
      <hardwareInterface>hardware_interface/VelocityJointInterface</hardwareInterface>
      <mechanicalReduction>1</mechanicalReduction>
    </actuator>
  </transmission>
  <transmission name="Joint_4_tran">
    <type>transmission_interface/SimpleTransmission</type>
    <joint name="Joint_4">
      <hardwareInterface>hardware_interface/VelocityJointInterface</hardwareInterface>
    </joint>
    <actuator name="Joint_4_actr">
      <hardwareInterface>hardware_interface/VelocityJointInterface</hardwareInterface>
      <mechanicalReduction>1</mechanicalReduction>
    </actuator>
  </transmission>
  <transmission name="Joint_5_tran">
    <type>transmission_interface/SimpleTransmission</type>
    <joint name="Joint_5">
      <hardwareInterface>hardware_interface/VelocityJointInterface</hardwareInterface>
    </joint>
    <actuator name="Joint_5_actr">
      <hardwareInterface>hardware_interface/VelocityJointInterface</hardwareInterface>
      <mechanicalReduction>1</mechanicalReduction>
    </actuator>
  </transmission>
  <transmission name="Gripper_tran">
    <type>transmission_interface/SimpleTransmission</type>
    <joint name="Gripper">
      <hardwareInterface>hardware_interface/VelocityJointInterface</hardwareInterface>
    </joint>
    <actuator name="Gripper_actr">
      <hardwareInterface>hardware_interface/VelocityJointInterface</hardwareInterface>
      <mechanicalReduction>1</mechanicalReduction>
    </actuator>
  </transmission>
  <!-- COMMENT OUT to let mimic joint control all gripper joints -->
  <!-- <transmission name="left_inner_back_joint_tran">
  <type>transmission_interface/SimpleTransmission</type>
  <joint name="left_inner_back_joint">
    <hardwareInterface>hardware_interface/VelocityJointInterface</hardwareInterface>
  </joint>
  <actuator name="left_inner_back_joint_actr">
    <hardwareInterface>hardware_interface/VelocityJointInterface</hardwareInterface>
    <mechanicalReduction>1</mechanicalReduction>
  </actuator>
</transmission>

<transmission name="right_outer_back_joint_tran">
  <type>transmission_interface/SimpleTransmission</type>
  <joint name="right_outer_back_joint">
    <hardwareInterface>hardware_interface/VelocityJointInterface</hardwareInterface>
  </joint>
  <actuator name="right_outer_back_joint_actr">
    <hardwareInterface>hardware_interface/VelocityJointInterface</hardwareInterface>
    <mechanicalReduction>1</mechanicalReduction>
  </actuator>
</transmission>

<transmission name="left_outer_back_joint_tran">
  <type>transmission_interface/SimpleTransmission</type>
  <joint name="left_outer_back_joint">
    <hardwareInterface>hardware_interface/VelocityJointInterface</hardwareInterface>
  </joint>
  <actuator name="left_outer_back_joint_actr">
    <hardwareInterface>hardware_interface/VelocityJointInterface</hardwareInterface>
    <mechanicalReduction>1</mechanicalReduction>
  </actuator>
</transmission> -->
  <!-- <transmission name="right_inner_front_joint_tran">
  <type>transmission_interface/SimpleTransmission</type>
  <joint name="right_inner_front_joint">
    <hardwareInterface>hardware_interface/VelocityJointInterface</hardwareInterface>
  </joint>
  <actuator name="right_inner_front_joint_actr">
    <hardwareInterface>hardware_interface/VelocityJointInterface</hardwareInterface>
    <mechanicalReduction>1</mechanicalReduction>
  </actuator>
</transmission>

<transmission name="left_inner_front_joint_tran">
  <type>transmission_interface/SimpleTransmission</type>
  <joint name="left_inner_front_joint">
    <hardwareInterface>hardware_interface/VelocityJointInterface</hardwareInterface>
  </joint>
  <actuator name="left_inner_front_joint_actr">
    <hardwareInterface>hardware_interface/VelocityJointInterface</hardwareInterface>
    <mechanicalReduction>1</mechanicalReduction>
  </actuator>
</transmission> -->
  <!-- <transmission name="right_outer_front_joint_tran">
  <type>transmission_interface/SimpleTransmission</type>
  <joint name="right_outer_front_joint">
    <hardwareInterface>hardware_interface/VelocityJointInterface</hardwareInterface>
  </joint>
  <actuator name="right_outer_front_joint_actr">
    <hardwareInterface>hardware_interface/VelocityJointInterface</hardwareInterface>
    <mechanicalReduction>1</mechanicalReduction>
  </actuator>
</transmission>

<transmission name="left_outer_front_joint_tran">
  <type>transmission_interface/SimpleTransmission</type>
  <joint name="left_outer_front_joint">
    <hardwareInterface>hardware_interface/VelocityJointInterface</hardwareInterface>
  </joint>
  <actuator name="left_outer_front_joint_actr">
    <hardwareInterface>hardware_interface/VelocityJointInterface</hardwareInterface>
    <mechanicalReduction>1</mechanicalReduction>
  </actuator>
</transmission> -->
  <!-- <gazebo>
    <plugin filename="libroboticsgroup_upatras_gazebo_mimic_joint_plugin.so" name="mimic_joint_plugin">
      <joint>Gripper</joint>
      <mimicJoint>left_inner_back_joint</mimicJoint>
      <multiplier>1.0</multiplier>
      <offset>0</offset>
      <maxEffort>10.0</maxEffort>
    </plugin>
  </gazebo>
  <gazebo>
    <plugin filename="libroboticsgroup_upatras_gazebo_mimic_joint_plugin.so" name="mimic_joint_plugin">
      <joint>Gripper</joint>
      <mimicJoint>left_outer_back_joint</mimicJoint>
      <multiplier>1.0</multiplier>
      <offset>0</offset>
      <maxEffort>10.0</maxEffort>
    </plugin>
  </gazebo>
  <gazebo>
    <plugin filename="libroboticsgroup_upatras_gazebo_mimic_joint_plugin.so" name="mimic_joint_plugin">
      <joint>Gripper</joint>
      <mimicJoint>right_outer_back_joint</mimicJoint>
      <multiplier>1.0</multiplier>
      <offset>0</offset>
      <maxEffort>10.0</maxEffort>
    </plugin>
  </gazebo>
  <gazebo>
    <plugin filename="libroboticsgroup_upatras_gazebo_mimic_joint_plugin.so" name="mimic_joint_plugin">
      <joint>Gripper</joint>
      <mimicJoint>left_inner_front_joint</mimicJoint>
      <multiplier>1.0</multiplier>
      <offset>0</offset>
      <maxEffort>10.0</maxEffort>
    </plugin>
  </gazebo>
  <gazebo>
    <plugin filename="libroboticsgroup_upatras_gazebo_mimic_joint_plugin.so" name="mimic_joint_plugin">
      <joint>Gripper</joint>
      <mimicJoint>right_inner_front_joint</mimicJoint>
      <multiplier>1.0</multiplier>
      <offset>0</offset>
      <maxEffort>10.0</maxEffort>
    </plugin>
  </gazebo>
  <gazebo>
    <plugin filename="libgazebo_ros_control.so" name="gazebo_ros_control">
      <controlPeriod>0.001</controlPeriod>
    </plugin>
  </gazebo> -->

  <gazebo>
    <plugin filename="gz_ros2_control-system" name="gz_ros2_control::GazeboSimROS2ControlPlugin">
      <parameters>$(find amir_gazebo)/launch/amir_controllers.yaml</parameters>
    </plugin>
  </gazebo>
  <gazebo reference="link0_1">
    <material>Gazebo/Silver</material>
    <mu1>1.4</mu1>
    <mu2>1.4</mu2>
    <selfCollide>true</selfCollide>
    <gravity>true</gravity>
  </gazebo>
  <gazebo reference="link1_1">
    <material>Gazebo/Silver</material>
    <mu1>1.4</mu1>
    <mu2>1.4</mu2>
    <selfCollide>true</selfCollide>
  </gazebo>
  <gazebo reference="link2_1">
    <material>Gazebo/Silver</material>
    <mu1>1.4</mu1>
    <mu2>1.4</mu2>
    <selfCollide>true</selfCollide>
  </gazebo>
  <gazebo reference="link3_1">
    <material>Gazebo/Silver</material>
    <mu1>1.4</mu1>
    <mu2>1.4</mu2>
    <selfCollide>true</selfCollide>
  </gazebo>
  <gazebo reference="link4_1">
    <material>Gazebo/Silver</material>
    <mu1>1.4</mu1>
    <mu2>1.4</mu2>
    <selfCollide>true</selfCollide>
  </gazebo>
  <gazebo reference="tcp_link">
    <material>Gazebo/RedTransparent</material>
  </gazebo>
  <gazebo reference="gripper_base_1">
    <material>Gazebo/Silver</material>
    <mu1>1.4</mu1>
    <mu2>1.4</mu2>
    <selfCollide>true</selfCollide>
  </gazebo>
  <gazebo reference="inner_link_left_1">
    <material>Gazebo/Silver</material>
    <mu1>1.4</mu1>
    <mu2>1.4</mu2>
    <selfCollide>false</selfCollide>
  </gazebo>
  <gazebo reference="outer_link_right_1">
    <material>Gazebo/Silver</material>
    <mu1>1.4</mu1>
    <mu2>1.4</mu2>
    <selfCollide>false</selfCollide>
  </gazebo>
  <gazebo reference="outer_link_left_1">
    <material>Gazebo/Silver</material>
    <mu1>1.4</mu1>
    <mu2>1.4</mu2>
    <selfCollide>false</selfCollide>
  </gazebo>
  <gazebo reference="finger_right_1">
    <material>Gazebo/Silver</material>
    <mu1>1.4</mu1>
    <mu2>1.4</mu2>
    <selfCollide>false</selfCollide>
  </gazebo>
  <gazebo reference="finger_left_1">
    <material>Gazebo/Silver</material>
    <mu1>1.4</mu1>
    <mu2>1.4</mu2>
    <selfCollide>false</selfCollide>
  </gazebo>
  <gazebo reference="inner_link_right_1">
    <material>Gazebo/Silver</material>
    <mu1>1.4</mu1>
    <mu2>1.4</mu2>
    <selfCollide>false</selfCollide>
  </gazebo>
  <link name="link0_1">
    <inertial>
      <origin rpy="0 0 0" xyz="0.0 -0.018171 -0.164351"/>
      <mass value="2.37148"/>
      <inertia ixx="0.01020" ixy="-0.000000291275" ixz="0.000000428733" iyy="0.008745" iyz="-0.0001135" izz="0.008637"/>
    </inertial>
    <visual>
      <origin rpy="0 0 0" xyz="0 0 0"/>
      <geometry>
        <mesh filename="package://amir_description/meshes/base_link.stl" scale="0.001 0.001 0.001"/>
      </geometry>
      <material name="silver-amir"/>
    </visual>
    <collision>
      <origin rpy="0 0 0" xyz="0 0 0"/>
      <geometry>
        <mesh filename="package://amir_description/meshes/base_link.stl" scale="0.001 0.001 0.001"/>
      </geometry>
    </collision>
  </link>
  <link name="link1_1">
    <inertial>
      <origin rpy="0 0 0" xyz="0.00 -0.015481739081542548 0.052015680869348734"/>
      <mass value="1.530171"/>
      <inertia ixx="0.003518" ixy="0.0002342" ixz="-0.000060488629" iyy="0.003654" iyz="0.00002134302" izz="0.004561"/>
    </inertial>
    <visual>
      <origin rpy="0 0 0" xyz="0.00 0.001523 0.097"/>
      <geometry>
        <mesh filename="package://amir_description/meshes/link1_1.stl" scale="0.001 0.001 0.001"/>
      </geometry>
      <material name="silver-amir"/>
    </visual>
    <collision>
      <origin rpy="0 0 0" xyz="0.00 0.001523 0.097"/>
      <geometry>
        <mesh filename="package://amir_description/meshes/link1_1.stl" scale="0.001 0.001 0.001"/>
      </geometry>
    </collision>
  </link>
  <link name="link2_1">
    <inertial>
      <origin rpy="0 0 0" xyz="0.00 0.13301271963728503 0.014415028610505691"/>
      <mass value="1.863224"/>
      <inertia ixx="0.01781" ixy="0.002226" ixz="0.0002878" iyy="0.003563" iyz="-0.0008328" izz="0.02037"/>
    </inertial>
    <visual>
      <origin rpy="0 0 0" xyz="0.0 0.001523 -0.0"/>
      <geometry>
        <mesh filename="package://amir_description/meshes/link2_1.stl" scale="0.001 0.001 0.001"/>
      </geometry>
      <material name="silver-amir"/>
    </visual>
    <collision>
      <origin rpy="0 0 0" xyz="0.0 0.001523 -0.0"/>
      <geometry>
        <mesh filename="package://amir_description/meshes/link2_1.stl" scale="0.001 0.001 0.001"/>
      </geometry>
    </collision>
  </link>
  <link name="link3_1">
    <inertial>
      <origin rpy="0 0 0" xyz="-0.0 0.11541444998364736 0.013649097933998836"/>
      <mass value="0.904315"/>
      <inertia ixx="0.01374" ixy="0.0004506" ixz="0.000064200508" iyy="0.0009585" iyz="-0.0007046" izz="0.01392"/>
    </inertial>
    <visual>
      <origin rpy="0 0 0" xyz="-0.0 -0.308477 0.0"/>
      <geometry>
        <mesh filename="package://amir_description/meshes/link3_1.stl" scale="0.001 0.001 0.001"/>
      </geometry>
      <material name="silver-amir"/>
    </visual>
    <collision>
      <origin rpy="0 0 0" xyz="-0.0 -0.308477 0.0"/>
      <geometry>
        <mesh filename="package://amir_description/meshes/link3_1.stl" scale="0.001 0.001 0.001"/>
      </geometry>
    </collision>
  </link>
  <link name="link4_1">
    <inertial>
      <origin rpy="0 0 0" xyz="0.0 0.002871377179418988 -2.4706069597529916e-10"/>
      <mass value="0.261183"/>
      <inertia ixx="0.000153" ixy="0.000007504862" ixz="-0.000000007056" iyy="0.000144" iyz="-0.000000008483" izz="0.0001626"/>
    </inertial>
    <visual>
      <origin rpy="0 0 0" xyz="0.0 -0.618477 -0.0"/>
      <geometry>
        <mesh filename="package://amir_description/meshes/link4_1.stl" scale="0.001 0.001 0.001"/>
      </geometry>
      <material name="silver-amir"/>
    </visual>
    <collision>
      <origin rpy="0 0 0" xyz="0.0 -0.618477 -0.0"/>
      <geometry>
        <mesh filename="package://amir_description/meshes/link4_1.stl" scale="0.001 0.001 0.001"/>
      </geometry>
    </collision>
  </link>
  <!-- add tool center point link for easier visualization -->
  <link name="tcp_link">
    <visual>
      <geometry>
        <box size="0.01 0.01 0.01"/>
      </geometry>
      <material name="red">
        <color rgba="1.0 0.0 0.0 0.6"/>
      </material>
    </visual>
  </link>
  <joint name="tcp_fixed" type="fixed">
    <origin rpy="0 0 0" xyz="0.0 0.0795 0.0"/>
    <parent link="gripper_base_1"/>
    <child link="tcp_link"/>
  </joint>
  <link name="gripper_base_1">
    <inertial>
      <origin rpy="0 0 0" xyz="0.0 0.01128514374633649 -0.004836003736858561"/>
      <mass value="0.130337"/>
      <inertia ixx="0.00008551164" ixy="-0.000003161031" ixz="-0.000003519581" iyy="0.0001216" iyz="0.000001110492" izz="0.000059771966"/>
    </inertial>
    <visual>
      <origin rpy="0 0 0" xyz="0.0 -0.658977 -0.0"/>
      <geometry>
        <mesh filename="package://amir_description/meshes/gripper_base_1.stl" scale="0.001 0.001 0.001"/>
      </geometry>
      <material name="silver-amir"/>
    </visual>
    <collision>
      <origin rpy="0 0 0" xyz="0.0 -0.658977 -0.0"/>
      <geometry>
        <mesh filename="package://amir_description/meshes/gripper_base_1.stl" scale="0.001 0.001 0.001"/>
      </geometry>
    </collision>
  </link>
  <link name="inner_link_left_1">
    <inertial>
      <origin rpy="0 0 0" xyz="0.004775263006022466 0.014691054356398392 0.0"/>
      <mass value="0.010214"/>
      <inertia ixx="0.000007990586" ixy="-0.000000446816" ixz="-0.00000" iyy="0.000005973968" iyz="0.0000" izz="0.000002702176"/>
    </inertial>
    <visual>
      <origin rpy="0 0 0" xyz="0.018 -0.679499 -0.0"/>
      <geometry>
        <mesh filename="package://amir_description/meshes/inner_link_left_1.stl" scale="0.001 0.001 0.001"/>
      </geometry>
      <material name="silver-amir"/>
    </visual>
    <collision>
      <origin rpy="0 0 0" xyz="0.018 -0.679499 -0.0"/>
      <geometry>
        <mesh filename="package://amir_description/meshes/inner_link_left_1.stl" scale="0.001 0.001 0.001"/>
      </geometry>
    </collision>
  </link>
  <link name="outer_link_right_1">
    <inertial>
      <origin rpy="0 0 0" xyz="0.0029741808490290345 0.020000417105897617 0.0"/>
      <mass value="0.015216"/>
      <inertia ixx="0.000009064719" ixy="0.000000861905" ixz="0.0" iyy="0.000006207691" iyz="-0.0" izz="0.000003674706"/>
    </inertial>
    <visual>
      <origin rpy="0 0 0" xyz="-0.038 -0.679499 -0.0"/>
      <geometry>
        <mesh filename="package://amir_description/meshes/outer_link_right_1.stl" scale="0.001 0.001 0.001"/>
      </geometry>
      <material name="silver-amir"/>
    </visual>
    <collision>
      <origin rpy="0 0 0" xyz="-0.038 -0.679499 -0.0"/>
      <geometry>
        <mesh filename="package://amir_description/meshes/outer_link_right_1.stl" scale="0.001 0.001 0.001"/>
      </geometry>
    </collision>
  </link>
  <link name="outer_link_left_1">
    <inertial>
      <origin rpy="0 0 0" xyz="-0.002974180849028861 0.020000417105899837 0.0"/>
      <mass value="0.015216"/>
      <inertia ixx="0.000009073869" ixy="-0.000000846555" ixz="0.00000" iyy="0.000006198542" iyz="0.00000" izz="0.000003674706"/>
    </inertial>
    <visual>
      <origin rpy="0 0 0" xyz="0.038 -0.679499 -0.0"/>
      <geometry>
        <mesh filename="package://amir_description/meshes/outer_link_left_1.stl" scale="0.001 0.001 0.001"/>
      </geometry>
      <material name="silver-amir"/>
    </visual>
    <collision>
      <origin rpy="0 0 0" xyz="0.038 -0.679499 -0.0"/>
      <geometry>
        <mesh filename="package://amir_description/meshes/outer_link_left_1.stl" scale="0.001 0.001 0.001"/>
      </geometry>
    </collision>
  </link>
  <!-- NOTE: urdf doesnt support kinematic closed loop, 
so we need to left one on the joints open -->
  <!-- use this when using inner link -->
  <link name="finger_right_1">
    <inertial>
      <origin rpy="0 0 0" xyz="0.002489444086893569 0.012411313372935995 0.0"/>
      <mass value="0.022898"/>
      <inertia ixx="0.000017128826" ixy="0.000001953953" ixz="-0.00" iyy="0.000011930401" iyz="0.00" izz="0.000008715513"/>
    </inertial>
    <visual>
      <origin rpy="0 0 0" xyz="-0.018 -0.719499 -0.0"/>
      <geometry>
        <mesh filename="package://amir_description/meshes/finger_right_1.stl" scale="0.001 0.001 0.001"/>
      </geometry>
      <material name="silver-amir"/>
    </visual>
    <collision>
      <origin rpy="0 0 0" xyz="-0.018 -0.719499 -0.0"/>
      <geometry>
        <mesh filename="package://amir_description/meshes/finger_right_1.stl" scale="0.001 0.001 0.001"/>
      </geometry>
    </collision>
  </link>
  <link name="finger_left_1">
    <inertial>
      <origin rpy="0 0 0" xyz="-0.0024894440868974757 0.012411313372938326 0.0"/>
      <mass value="0.022898"/>
      <inertia ixx="0.000017128826" ixy="-0.000001953953" ixz="-0.00" iyy="0.000011930401" iyz="0.00" izz="0.000008715513"/>
    </inertial>
    <visual>
      <origin rpy="0 0 0" xyz="0.018 -0.719499 -0.0"/>
      <geometry>
        <mesh filename="package://amir_description/meshes/finger_left_1.stl" scale="0.001 0.001 0.001"/>
      </geometry>
      <material name="silver-amir"/>
    </visual>
    <collision>
      <origin rpy="0 0 0" xyz="0.018 -0.719499 -0.0"/>
      <geometry>
        <mesh filename="package://amir_description/meshes/finger_left_1.stl" scale="0.001 0.001 0.001"/>
      </geometry>
    </collision>
  </link>
  <!-- end of inner link -->
  <!-- use this when using outer link -->
  <!-- <link name="finger_right_1">
  <inertial>
    <origin xyz="-0.01751055591310643 0.012411313372935995 0.0" rpy="0 0 0"/>
    <mass value="0.08357364665097004"/>
    <inertia ixx="6.7e-05" iyy="4.7e-05" izz="3.5e-05" ixy="8e-06" iyz="0.0" ixz="-0.0"/>
  </inertial>
  <visual>
    <origin xyz="-0.038 -0.719499 -0.0" rpy="0 0 0"/>
    <geometry>
      <mesh filename="package://amir_description/meshes/finger_right_1.stl" scale="0.001 0.001 0.001"/>
    </geometry>
    <material name="silver-amir"/>
  </visual>
  <collision>
    <origin xyz="-0.038 -0.719499 -0.0" rpy="0 0 0"/>
    <geometry>
      <mesh filename="package://amir_description/meshes/finger_right_1.stl" scale="0.001 0.001 0.001"/>
    </geometry>
  </collision>
</link>

<link name="finger_left_1">
  <inertial>
    <origin xyz="0.017510555913102525 0.012411313372938326 0.0" rpy="0 0 0"/>
    <mass value="0.08357364665097004"/>
    <inertia ixx="6.7e-05" iyy="4.7e-05" izz="3.5e-05" ixy="-8e-06" iyz="-0.0" ixz="-0.0"/>
  </inertial>
  <visual>
    <origin xyz="0.038 -0.719499 -0.0" rpy="0 0 0"/>
    <geometry>
      <mesh filename="package://amir_description/meshes/finger_left_1.stl" scale="0.001 0.001 0.001"/>
    </geometry>
    <material name="silver-amir"/>
  </visual>
  <collision>
    <origin xyz="0.038 -0.719499 -0.0" rpy="0 0 0"/>
    <geometry>
      <mesh filename="package://amir_description/meshes/finger_left_1.stl" scale="0.001 0.001 0.001"/>
    </geometry>
  </collision>
</link> -->
  <!-- end of outer link -->
  <link name="inner_link_right_1">
    <inertial>
      <origin rpy="0 0 0" xyz="-0.003238561697949489 0.01183851365994859 0.0"/>
      <mass value="0.009152"/>
      <inertia ixx="0.000006905758" ixy="0.000000349609" ixz="-0.000000039247" iyy="0.000005170951" iyz="0.000000273496" izz="0.000002372537"/>
    </inertial>
    <visual>
      <origin rpy="0 0 0" xyz="-0.018 -0.679499 -0.0"/>
      <geometry>
        <mesh filename="package://amir_description/meshes/inner_link_right_1.stl" scale="0.001 0.001 0.001"/>
      </geometry>
      <material name="silver-amir"/>
    </visual>
    <collision>
      <origin rpy="0 0 0" xyz="-0.018 -0.679499 -0.0"/>
      <geometry>
        <mesh filename="package://amir_description/meshes/inner_link_right_1.stl" scale="0.001 0.001 0.001"/>
      </geometry>
    </collision>
  </link>
  <!--
  - Refer here about how to set each parameters: 
  - http://wiki.ros.org/urdf/XML/joint#Elements 
  - units (revolute joints):
  - effort  : N∙m
  - velocity: rad/s
  - damping : N∙m∙s/rad
  - friction: N∙m
-->
  <joint name="Joint_1" type="revolute">
    <origin rpy="0 0 0" xyz="-0.0 -0.001523 -0.097"/>
    <parent link="link0_1"/>
    <child link="link1_1"/>
    <axis xyz="0.0 0.0 1.0"/>
    <limit effort="33" lower="-2.96706" upper="2.96706" velocity="1"/>
    <dynamics damping="0.6" friction="0.3"/>
  </joint>
  <joint name="Joint_2" type="revolute">
    <origin rpy="0 0 0" xyz="-0.0 0.0 0.097"/>
    <parent link="link1_1"/>
    <child link="link2_1"/>
    <axis xyz="1.0 0.0 0.0"/>
    <limit effort="22" lower="0" upper="2.356194" velocity="1"/>
    <dynamics damping="0.6" friction="0.3"/>
  </joint>
  <joint name="Joint_3" type="revolute">
    <origin rpy="0 0 0" xyz="0.0 0.31 -0.0"/>
    <parent link="link2_1"/>
    <child link="link3_1"/>
    <axis xyz="1.0 0.0 0.0"/>
    <limit effort="26" lower="-2.792527" upper="0.0" velocity="1"/>
    <dynamics damping="0.6" friction="0.3"/>
  </joint>
  <joint name="Joint_4" type="revolute">
    <origin rpy="0 0 0" xyz="-0.0 0.31 0.0"/>
    <parent link="link3_1"/>
    <child link="link4_1"/>
    <axis xyz="1.0 0.0 0.0"/>
    <limit effort="1.3" lower="-2.094395" upper="1.308997" velocity="1"/>
    <dynamics damping="0.3" friction="0.1"/>
  </joint>
  <joint name="Joint_5" type="revolute">
    <origin rpy="0 0 0" xyz="0.0 0.0405 0.0"/>
    <parent link="link4_1"/>
    <child link="gripper_base_1"/>
    <axis xyz="0.0 1.0 0.0"/>
    <limit effort="0.4" lower="-2.75762" upper="2.75762" velocity="2"/>
    <dynamics damping="0.3" friction="0.1"/>
  </joint>
  <joint name="Gripper" type="revolute">
    <origin rpy="0 0 0" xyz="0.018367 0.020522 0.0"/>
    <parent link="gripper_base_1"/>
    <child link="inner_link_right_1"/>
    <axis xyz="0.0 0.0 1.0"/>
    <limit effort="0.4" lower="-1.047198" upper="0.261799" velocity="2"/>
  </joint>
  <joint name="left_inner_back_joint" type="continuous">
    <origin rpy="0 0 0" xyz="-0.017633 0.020522 0.0"/>
    <parent link="gripper_base_1"/>
    <child link="inner_link_left_1"/>
    <axis xyz="0.0 0.0 -1.0"/>
    <!-- <limit lower="-1.047198" upper="0.261799" effort="10" velocity="4"/> -->
    <mimic joint="Gripper" multiplier="1" offset="0"/>
  </joint>
  <joint name="right_outer_back_joint" type="continuous">
    <origin rpy="0 0 0" xyz="0.038367 0.020522 0.0"/>
    <parent link="gripper_base_1"/>
    <child link="outer_link_right_1"/>
    <axis xyz="0.0 0.0 1.0"/>
    <!-- <limit lower="-1.047198" upper="0.261799" effort="10" velocity="4"/> -->
    <mimic joint="Gripper" multiplier="1" offset="0"/>
  </joint>
  <joint name="left_outer_back_joint" type="continuous">
    <origin rpy="0 0 0" xyz="-0.037633 0.020522 0.0"/>
    <parent link="gripper_base_1"/>
    <child link="outer_link_left_1"/>
    <axis xyz="0.0 0.0 -1.0"/>
    <!-- <limit lower="-1.047198" upper="0.261799" effort="10" velocity="4"/> -->
    <mimic joint="Gripper" multiplier="1" offset="0"/>
  </joint>
  <!-- use this when using inner joint -->
  <joint name="right_inner_front_joint" type="continuous">
    <origin rpy="0 0 0" xyz="0.0 0.04 0.0"/>
    <parent link="inner_link_right_1"/>
    <child link="finger_right_1"/>
    <axis xyz="0.0 0.0 -1.0"/>
    <!-- <limit lower="-1.047198" upper="0.261799" effort="10" velocity="4"/> -->
    <mimic joint="Gripper" multiplier="1" offset="0"/>
  </joint>
  <joint name="left_inner_front_joint" type="continuous">
    <origin rpy="0 0 0" xyz="-0.0 0.04 0.0"/>
    <parent link="inner_link_left_1"/>
    <child link="finger_left_1"/>
    <axis xyz="0.0 0.0 1.0"/>
    <!-- <limit lower="-1.047198" upper="0.261799" effort="10" velocity="4"/> -->
    <mimic joint="Gripper" multiplier="1" offset="0"/>
  </joint>
  <!-- end of inner joint -->
  <!-- use this when using outer joint -->
  <!-- <joint name="right_outer_front_joint" type="revolute">
  <origin xyz="0.0 0.04 0.0" rpy="0 0 0"/>
  <parent link="outer_link_right_1"/>
  <child link="finger_right_1"/>
  <axis xyz="0.0 0.0 -1.0"/>
  <limit lower="-1.047198" upper="0.261799" effort="10" velocity="4"/>
  <mimic joint="Gripper" multiplier="1" offset="0" />
</joint>

<joint name="left_outer_front_joint" type="revolute">
  <origin xyz="0.0 0.04 0.0" rpy="0 0 0"/>
  <parent link="outer_link_left_1"/>
  <child link="finger_left_1"/>
  <axis xyz="-0.0 0.0 1.0"/>
  <limit lower="-1.047198" upper="0.261799" effort="10" velocity="4"/>
  <mimic joint="Gripper" multiplier="1" offset="0" />
</joint> -->
  <!-- end of outer joint -->
  <joint name="base_fixed" type="fixed">
    <origin rpy="0 0 0" xyz="0.0 0.0 0.413"/>
    <parent link="base_link"/>
    <child link="link0_1"/>
  </joint>
</robot>
